Workbook

Sheet Contents
B4: Deaths in Australia web report
B5: Released 09 April 2025
B6: Supplementary tables
B8: Contents
B9: ='Table S2.1'!A1 -> Table S2.1: Deaths by sex and age group, 2023
B10: ='Table S2.2'!A1 -> Table S2.2: Child deaths (aged 0–4), number, per cent of all deaths and rates (per 100,000 population), by sex, 1907–2023
B11: ='Table S2.3'!A1 -> Table S2.3: Potential years of life lost before age 75, number and rate, by sex, 1907–2023
B12: ='Table S3.1'!A1 -> Table S3.1: Leading underlying causes of death, number, per cent of all deaths and age-standardised death rates, by sex, 2023
B13: ='Table S3.2'!A1 -> Table S3.2: Leading underlying causes of death, number, per cent of all deaths and age-specific rates, by sex and age group, 2023
B14: ='Table S4.1'!A1 -> Table S4.1: Deaths due to COVID-19, number and age-specific rates, by age and sex, 2023
B15: ='Table S5.1'!A1 -> Table S5.1: Potentially avoidable deaths (among people aged under 75), numbers, per cent and rates, by sex, 1997–2023
B16: ='Table S5.2'!A1 -> Table S5.2: Potentially avoidable causes of death (among people aged under 75), number, per cent and rates (deaths per 100,000 population), by sex and broad cause groups, 2023
B17: ='Table S5.3'!A1 -> Table S5.3: Leading potentially avoidable deaths (among people aged under 75), number, per cent and rates (deaths per 100,000 population), by sex, 2023
B18: ='Table S6.1'!A1 -> Table S6.1: Deaths, number and rates, by sex, 1907–2023
B19: ='Table S6.2'!A1 -> Table S6.2: Deaths by broad cause of death, number and rates, 1907–2023
B20: ='Table S6.3'!A1 -> Table S6.3: Leading underlying causes of death, number, per cent of all deaths and age-standardised death rates, by sex, 2013
B21: ='Table S6.4'!A1 -> Table S6.4: Leading underlying causes of death, number, per cent of all deaths and age-standardised death rates, by sex, 2013–2023
B22: ='Table S7.1'!A1 -> Table S7.1: Leading underlying causes of death, number, per cent of all deaths and rates, Aboriginal and Torres Strait Islander (First Nations) people, NSW, Qld, WA, SA and NT, 2021-2023
B23: Table S7.2: Leading underlying causes of death, number, per cent of all deaths and rates, non-Indigenous people, NSW, Qld, WA, SA and NT, 2021-2023
B24: ='Table S7.3'!A1 -> Table S7.3: Leading potentially avoidable cause of death (among people aged under 75), number, per cent and rates, by Indigenous status and sex, NSW, Qld, WA, SA and NT, 2021-2023
B25: ='Table S7.4'!A1 -> Table S7.4: Leading underlying causes of death, number, per cent and rates, by sex and Remoteness area, 2021-2023
B26: ='Table S7.5'!A1 -> Table S7.5: Leading potentially avoidable cause of death (among people aged under 75), number, per cent and rates, by sex and Remoteness area, 2021–2023
B27: ='Table S7.6'!A1 -> Table S7.6: Leading underlying causes of death, number, per cent and rates, by sex and Socioeconomic area, 2021-2023
B28: ='Table S7.7'!A1 -> Table S7.7: Leading potentially avoidable cause of death (among people aged under 75), number, per cent and rates, by sex, by sex and Socioeconomic area, 2021–2023
B29: ='Table S8.1'!A1 -> Table S8.1: Number of deaths and number of causes recorded per death (%), 2015, 2019 and 2023
B30: ='Table S8.2'!A1 -> Table S8.2: Number of deaths, number of causes, and average number of causes per death, by sex and age group, for years 2015, 2019 and 2023
B31: ='Table S8.3'!A1 -> Table S8.3: Average number of causes per death, by cause group of the underlying cause, 2023
B32: ='Table S8.4'!A1 -> Table S8.4: Cause of death, per cent involvement by cause type, cause group and specific causes, 2023
B33: ='Table S8.5'!A1 -> Table S8.5: Most common causes of death, number and per cent of deaths, by cause type and sex, 2023
B34: ='Table S8.6'!A1 -> Table S8.6: Most common causes of death, number and per cent of deaths, by cause type and age group, 2023
B35: ='Table S8.7'!A1 -> Table S8.7: Most commonly involved psychosocial factors, coroner-referred deaths, number and per cent , by sex, 2023
B36: ='Table S8.8'!A1 -> Table S8.8: Most common psychosocial factors, coroner-referred deaths, number and per cent of deaths, by underlying cause and sex, 2023
B37: ='Table S8.9'!A1 -> Table S8.9: Most common psychosocial factors, coroner-referred deaths, number and per cent of deaths, by sex and age group, 2023
B38: ='Table S8.10'!A1 -> Table S8.10: Most common causes of death, number and per cent of deaths, by cause type and Socioeconomic area, 2021–2023
B39: ='Table S8.11'!A1 -> Table S8.11: Most commonly recorded psychosocial factors, coroner-referred deaths, number and per cent of deaths, by sex and Socioeconomic area (quintile), 2021–2023
B40: Table S8.12: Coroner-referred deaths, number and per cent with at least one psychosocial factor, 2023
B41: ='Table S9.1'!A1 -> Table S9.1: Life expectancy (expected age at death in years) at different ages by sex, 1881–1890 to 2021–2023
B42: ='Table S9.2'!A1 -> Table S9.2: Life expectancy (years) at birth by sex, OECD countries, 2023 (or nearest available year)

Sheet Table S2.1
A1: Table S2.1: Deaths by sex and age group, 2023
A2: Back to contents
A3: Age group | B3: Males | C3: Females | D3: Persons
A4: 0–4 | B4: 609 | C4: 476 | D4: 1085
A5: 5–9 | B5: 75 | C5: 55 | D5: 130
A6: 10–14 | B6: 99 | C6: 69 | D6: 168
A7: 15–19 | B7: 322 | C7: 123 | D7: 445
A8: 20–24 | B8: 481 | C8: 185 | D8: 666
A9: 25–29 | B9: 621 | C9: 274 | D9: 895
A10: 30–34 | B10: 716 | C10: 386 | D10: 1102
A11: 35–39 | B11: 926 | C11: 517 | D11: 1443
A12: 40–44 | B12: 1303 | C12: 766 | D12: 2069
A13: 45–49 | B13: 1749 | C13: 1027 | D13: 2776
A14: 50–54 | B14: 2724 | C14: 1680 | D14: 4404
A15: 55–59 | B15: 3666 | C15: 2258 | D15: 5924
... A26: Median age at death | B26: 79.55216 | C26: 84.60569 | D26: 81.9503
A27: Note: Year refers to year of registration of death.
A28: Source: AIHW National Mortality Database.

Sheet Table S2.2
A1: Table S2.2: Child deaths (aged 0–4), number, per cent of all deaths and rates (per 100,000 population), by sex, 1907–2023
A2: Back to contents
B3: Males | F3: Females | J3: Persons
A4: Year | B4: Number | C4: Per cent of total deaths (all ages) | D4: Rate (deaths per 100,000) | F4: Number | G4: Per cent of total deaths (all ages) | H4: Rate (deaths per 100,000) | J4: Number | K4: Per cent of total deaths (all ages) | L4: Rate (deaths per 100,000)
A5: 1907 | B5: 6482 | C5: 25 | D5: 2604 | F5: 5341 | G5: 27.6 | H5: 2213.7 | J5: 11823 | K5: 26.1 | L5: 2411.9
A6: 1908 | B6: 6339 | C6: 23.8 | D6: 2498.5 | F6: 5029 | G6: 25.4 | H6: 2047.1 | J6: 11368 | K6: 24.5 | L6: 2276.4
A7: 1909 | B7: 5927 | C7: 23.2 | D7: 2292.9 | F7: 4786 | G7: 25.7 | H7: 1913.9 | J7: 10713 | K7: 24.3 | L7: 2106.5
A8: 1910 | B8: 6404 | C8: 24.5 | D8: 2432.3 | F8: 5119 | G8: 26.3 | H8: 2011.7 | J8: 11523 | K8: 25.3 | L8: 2225.6
A9: 1911 | B9: 6126 | C9: 22.2 | D9: 2285.2 | F9: 4871 | G9: 24 | H9: 1881.8 | J9: 10997 | K9: 23 | L9: 2087
A10: 1912 | B10: 7222 | C10: 23.8 | D10: 2655.2 | F10: 5698 | G10: 26 | H10: 2169.9 | J10: 12920 | K10: 24.8 | L10: 2416.8
A11: 1913 | B11: 7183 | C11: 24.1 | D11: 2603.3 | F11: 5835 | G11: 26.6 | H11: 2190.8 | J11: 13018 | K11: 25.1 | L11: 2400.7
A12: 1914 | B12: 7277 | C12: 24.4 | D12: 2600.4 | F12: 5746 | G12: 26.3 | H12: 2127.5 | J12: 13023 | K12: 25.2 | L12: 2368.1
A13: 1915 | B13: 6989 | C13: 22.8 | D13: 2463 | F13: 5523 | G13: 25 | H13: 2016.9 | J13: 12512 | K13: 23.7 | L13: 2243.9
A14: 1916 | B14: 7185 | C14: 23.2 | D14: 2497.5 | F14: 5828 | G14: 25.1 | H14: 2099.6 | J14: 13013 | K14: 24 | L14: 2302.1
A15: 1917 | B15: 5640 | C15: 20.4 | D15: 1934.1 | F15: 4247 | G15: 20.8 | H15: 1509.7 | J15: 9887 | K15: 20.6 | L15: 1725.7
A16: 1918 | B16: 5632 | C16: 19.7 | D16: 1905.7 | F16: 4575 | G16: 21.1 | H16: 1604.9 | J16: 10207 | K16: 20.3 | L16: 1758
... A121: 2023 | B121: 609 | C121: 0.6 | D121: 78.4 | F121: 476 | G121: 0.5 | H121: 64.7 | J121: 1085 | K121: 0.6 | L121: 71.8
A122: Notes
A123: 1. Year refers to year of registration of death.
A124: 2. Data is presented by year of registration of death. Prior to the 2022 data release, data was presented by the reference year in which the death was received and processed by the Australian Bureau of Statistics. As a result, data in this table may not equal previously published data for these years. For more detail, refer to Data collection: Presentation of mortality data in Causes of death, Australia, methodology, 2022 (https://www.abs.gov.au/methodologies/causes-death-australia-methodology/2022#data-collection)
A125: 3. Per cent of total deaths (all ages), described in table Table S6.1: Deaths by sex, number and rates (deaths per 100,000 population), 1907–2023.
A126: 4. Rates are calculated using the sum of estimated resident populations at 30 June for each year. Rates are expressed as deaths per 100,000 population.
A127: Source: AIHW National Mortality Database.

Sheet Table S2.3
A1: Table S2.3: Potential years of life lost before age 75, number and rate, by sex, 1907–2023
A2: Back to contents
B3: Males | E3: Females | H3: Persons
A4: Year | B4: Number (person-years) | C4: Rate (person-years per 1,000) | E4: Number (person-years) | F4: Rate (person-years per 1,000) | H4: Number (person-years) | I4: Rate (person-years per 1,000)
A5: 1907 | B5: 870650 | C5: 404.6 | E5: 705732.5 | F5: 356.4 | H5: 1576382.5 | I5: 381.5
A6: 1908 | B6: 880792.5 | C6: 403.2 | E6: 705257.5 | F6: 350.3 | H6: 1586050 | I6: 377.8
A7: 1909 | B7: 831830 | C7: 375.2 | E7: 660180 | F7: 322.5 | H7: 1492010 | I7: 349.9
A8: 1910 | B8: 871410 | C8: 387.4 | E8: 687100 | F8: 330.3 | H8: 1558510 | I8: 359.9
A9: 1911 | B9: 880475 | C9: 385.9 | E9: 687372.5 | F9: 325.1 | H9: 1567847.5 | I9: 356.7
A10: 1912 | B10: 1002087.5 | C10: 430.6 | E10: 769617.5 | F10: 355.1 | H10: 1771705 | I10: 394.2
A11: 1913 | B11: 997285 | C11: 420.3 | E11: 777635 | F11: 350.2 | H11: 1774920 | I11: 386.4
A12: 1914 | B12: 999567.5 | C12: 413.3 | E12: 758992.5 | F12: 333.8 | H12: 1758560 | I12: 374.8
A13: 1915 | B13: 997180 | C13: 404.7 | E13: 754797.5 | F13: 324.4 | H13: 1751977.5 | I13: 365.7
A14: 1916 | B14: 1000457.5 | C14: 398.6 | E14: 798032.5 | F14: 335.3 | H14: 1798490 | I14: 367.8
A15: 1917 | B15: 833510 | C15: 326.2 | E15: 642595 | F15: 264 | H15: 1476105 | I15: 295.9
A16: 1918 | B16: 849867.5 | C16: 326.7 | E16: 674345 | F16: 271.2 | H16: 1524212.5 | I16: 299.6
... A121: 2023 | B121: 571549 | C121: 46.5 | E121: 341630 | F121: 27.8 | H121: 913179 | I121: 37.2
A122: Notes
A123: 1. Year refers to year of registration of death.
A124: 2. Potential years of life lost represents the total number of years not lived by an individual before an arbitrary upper limit to life, in this table age 75 years. From 1964 onward, PYLL is calculated based on age at death in single years. Prior to 1964, age at death in years is estimated using the midpoint of the 5 year age group (e.g. all persons age 0 to 4 are treated as age=2.5 years). PYLL is presented here in person-years.
A125: 3. Data is presented by year of registration of death. Prior to the 2022 data release, data was presented by the reference year in which the death was received and processed by the Australian Bureau of Statistics. As a result, data in this table may not equal previously published data for these years. For more detail, refer to Data collection: Presentation of mortality data in Causes of death, Australia, methodology, 2022 (https://www.abs.gov.au/methodologies/causes-death-australia-methodology/2022#data-collection)
A126: 4. Rates are calculated using the sum of estimated resident populations at 30 June for each year. PYLL is presented here as a rate of person-years per 1,000 population under age 75 years.
A127: Source: AIHW (2025) General Record of Incidence of Mortality (GRIM) books (2023): All causes combined, AIHW, Australian Government. https://www.aihw.gov.au/reports/life-expectancy-deaths/grim-books/contents/grim-excel-workbooks

Sheet Table S3.1
A1: Table S3.1: Leading underlying causes of death, number, per cent of all deaths and age-standardised death rates, by sex, 2023
A2: Back to contents
A3: Males | G3: Females | M3: Persons
A4: Rank | B4: Cause of death | C4: Number | D4: Per cent | E4: ASR (deaths per 100,000) | G4: Rank | H4: Cause of death | I4: Number | J4: Per cent | K4: ASR (deaths per 100,000) | M4: Rank | N4: Cause of death | O4: Number | P4: Per cent | Q4: ASR (deaths per 100,000)
A5: 1 | B5: Coronary heart disease (I20–I25) | C5: 10343 | D5: 10.8 | E5: 64.4 | G5: 1 | H5: Dementia including Alzheimer's disease (F01, F03, G30) | I5: 10574 | J5: 12.2 | K5: 46.9 | M5: 1 | N5: Coronary heart disease (I20–I25) | O5: 16922 | P5: 9.2 | Q5: 46.4
A6: 2 | B6: Dementia including Alzheimer's disease (F01, F03, G30) | C6: 6111 | D6: 6.4 | E6: 37.5 | G6: 2 | H6: Coronary heart disease (I20–I25) | I6: 6579 | J6: 7.6 | K6: 30.8 | M6: 2 | N6: Dementia including Alzheimer's disease (F01, F03, G30) | O6: 16685 | P6: 9.1 | Q6: 43
A7: 3 | B7: Lung cancer (C33, C34) | C7: 5194 | D7: 5.4 | E7: 31.8 | G7: 3 | H7: Cerebrovascular disease (I60–I69) | I7: 5263 | J7: 6.1 | K7: 24.7 | M7: 3 | N7: Cerebrovascular disease (I60–I69) | O7: 9359 | P7: 5.1 | Q7: 25.2
A8: 4 | B8: Cerebrovascular disease (I60–I69) | C8: 4096 | D8: 4.3 | E8: 25.3 | G8: 4 | H8: Lung cancer (C33, C34) | I8: 3782 | J8: 4.3 | K8: 20.2 | M8: 4 | N8: Lung cancer (C33, C34) | O8: 8976 | P8: 4.9 | Q8: 25.6
A9: 5 | B9: COPD (J40–J44) | C9: 3914 | D9: 4.1 | E9: 23.9 | G9: 5 | H9: COPD (J40–J44) | I9: 3500 | J9: 4 | K9: 17.6 | M9: 5 | N9: COPD (J40–J44) | O9: 7414 | P9: 4 | Q9: 20.4
A10: 6 | B10: Prostate cancer (C61) | C10: 3726 | D10: 3.9 | E10: 22.7 | G10: 6 | H10: Breast cancer (C50) | I10: 3215 | J10: 3.7 | K10: 17.7 | M10: 6 | N10: Diabetes (E10–E14) | O10: 5942 | P10: 3.2 | Q10: 16.5
A11: 7 | B11: Diabetes (E10–E14) | C11: 3288 | D11: 3.4 | E11: 20.4 | G11: 7 | H11: Diabetes (E10–E14) | I11: 2654 | J11: 3.1 | K11: 13.1 | M11: 7 | N11: Colorectal cancer (C18–C20, C26.0) | O11: 5372 | P11: 2.9 | Q11: 15.4
A12: 8 | B12: Colorectal cancer (C18–C20, C26.0) | C12: 2832 | D12: 2.9 | E12: 17.8 | G12: 8 | H12: Colorectal cancer (C18–C20, C26.0) | I12: 2540 | J12: 2.9 | K12: 13.3 | M12: 8 | N12: COVID-19 (U07.1, U07.2, U10.9) | O12: 5001 | P12: 2.7 | Q12: 13.3
A13: 9 | B13: COVID-19 (U07.1, U07.2, U10.9) | C13: 2644 | D13: 2.7 | E13: 16.2 | G13: 9 | H13: COVID-19 (U07.1, U07.2, U10.9) | I13: 2357 | J13: 2.7 | K13: 10.9 | M13: 9 | N13: Accidental falls (W00–W19) | O13: 4105 | P13: 2.2 | Q13: 10.8
A14: 10 | B14: Suicide (X60–X84, Y87.0) | C14: 2419 | D14: 2.5 | E14: 18 | G14: 10 | H14: Heart failure and complications and ill-defined heart disease (I50–I51) | I14: 2195 | J14: 2.5 | K14: 9.7 | M14: 10 | N14: Heart failure and complications and ill-defined heart disease (I50–I51) | O14: 4022 | P14: 2.2 | Q14: 10.5
A15: 11 | B15: Accidental falls (W00–W19) | C15: 2122 | D15: 2.2 | E15: 13.1 | G15: 11 | H15: Other ill-defined causes (R00–R94, R96–R99, I46.9, I95.9, I99, J96.0, J96.9, P28.5) | I15: 1998 | J15: 2.3 | K15: 10.1 | M15: 11 | N15: Other ill-defined causes (R00–R94, R96–R99, I46.9, I95.9, I99, J96.0, J96.9, P28.5) | O15: 3808 | P15: 2.1 | Q15: 11.1
A16: 12 | B16: Pancreatic cancer (C25) | C16: 1941 | D16: 2 | E16: 12 | G16: 12 | H16: Accidental falls (W00–W19) | I16: 1983 | J16: 2.3 | K16: 9 | M16: 12 | N16: Prostate cancer (C61) | O16: 3726 | P16: 2 | Q16: 10
... A24: 20 | B24: Influenza and pneumonia (J09–J18) | C24: 1375 | D24: 1.4 | E24: 8.6 | G24: 20 | H24: Ovarian cancer (C56) | I24: 1045 | J24: 1.2 | K24: 5.8 | M24: 20 | N24: Hypertensive disease (I10–I15) | O24: 2684 | P24: 1.5 | Q24: 7
B25: Leading 20 causes combined | C25: 61560 | D25: 64 | E25: 384.2 | H25: Leading 20 causes combined | I25: 58256 | J25: 67 | K25: 280 | N25: Leading 20 causes combined | O25: 115896 | P25: 63.3 | Q25: 318.5
B26: All causes | C26: 96180 | D26: 100 | E26: 604.8 | H26: All causes | I26: 86951 | J26: 100 | K26: 430.9 | N26: All causes | O26: 183131 | P26: 100 | Q26: 512.7
A27: ASR | B27: age-standardised rate
A28: COPD | B28: Chronic obstructive pulmonary disease
A29: .. | B29: not applicable
A30: Notes
A31: 1. Year refers to year of registration of death. Deaths registered in 2023 are based on the preliminary version and are subject to further revision by the Australian Bureau of Statistics.
A32: 2. Leading causes of death are based on underlying causes of death and classified using an AIHW-modified version of Becker R, Sivli J, Ma Fat, L'Hours A, Laurenti R (2006). A method for deriving leading causes of death. Bulletin of the World Health Organization 84: 297–304. International Statistical Classification of Diseases and Related Health Problems, 10th revision (ICD-10) codes are presented in parentheses.
A33: 3. Rates are expressed as deaths per 100,000 population. Age-standardised rates are directly standardised to the Australian estimated resident population at 30 June 2001.
A34: Source: AIHW National Mortality Database.

Sheet Table S3.2
A1: Table S3.2: Leading underlying causes of death, number, per cent of all deaths and age-specific rates, by sex and age group, 2023
A2: Back to contents
B3: Males | H3: Females | N3: Persons
A4: Age group and rank | B4: Cause of death | C4: Number | D4: Per cent | E4: Age-specific rates (deaths per 100,000) | G4: Age group and rank | H4: Cause of death | I4: Number | J4: Per cent | K4: Age-specific rates (deaths per 100,000) | M4: Age group and rank | N4: Cause of death | O4: Number | P4: Per cent | Q4: Age-specific rates (deaths per 100,000)
A5: Under 1 | G5: Under 1 | M5: Under 1
A6: 1 | B6: Certain conditions originating in the perinatal period, congenital malformations, deformations and chromosomal abnormalities (P00–P96, Q00–Q99 excl. P28.5) | C6: 406 | D6: 78.5 | E6: 271.2 | G6: 1 | H6: Certain conditions originating in the perinatal period, congenital malformations, deformations and chromosomal abnormalities (P00–P96, Q00–Q99 excl. P28.5) | I6: 324 | J6: 82.2 | K6: 229.2 | M6: 1 | N6: Certain conditions originating in the perinatal period, congenital malformations, deformations and chromosomal abnormalities (P00–P96, Q00–Q99 excl. P28.5) | O6: 730 | P6: 80.1 | Q6: 250.8
A7: 2 | B7: Other ill-defined causes (R00–R94, R96–R99, I46.9, I95.9, I99, J96.0, J96.9, P28.5) | C7: 53 | D7: 10.3 | E7: 35.4 | G7: 2 | H7: Other ill-defined causes (R00–R94, R96–R99, I46.9, I95.9, I99, J96.0, J96.9, P28.5) | I7: 27 | J7: 6.9 | K7: 19.1 | M7: 2 | N7: Other ill-defined causes (R00–R94, R96–R99, I46.9, I95.9, I99, J96.0, J96.9, P28.5) | O7: 80 | P7: 8.8 | Q7: 27.5
A8: 3 | B8: Sudden infant death syndrome (SIDS) (R95) | C8: 10 | D8: 1.9 | E8: 6.7 | G8: 3 | H8: Selected metabolic disorders excl. dehydration (E70–E89 excl. E86, E87) | I8: 4 | J8: 1 | K8: 2.8 | M8: 3 | N8: Sudden infant death syndrome (SIDS) (R95) | O8: 13 | P8: 1.4 | Q8: 4.5
A9: 4 | B9: Accidental threats to breathing (W75–W84) | C9: 7 | D9: 1.4 | E9: 4.7 | G9: 3 | H9: Accidental threats to breathing (W75–W84) | I9: 4 | J9: 1 | K9: 2.8 | M9: 4 | N9: Accidental threats to breathing (W75–W84) | O9: 11 | P9: 1.2 | Q9: 3.8
A10: 4 | B10: Selected metabolic disorders excl. dehydration (E70–E89 excl. E86, E87) | C10: 7 | D10: 1.4 | E10: 4.7 | G10: 3 | H10: Epilepsy and status epilepticus (G40, G41) | I10: 4 | J10: 1 | K10: 2.8 | M10: 4 | N10: Selected metabolic disorders excl. dehydration (E70–E89 excl. E86, E87) | O10: 11 | P10: 1.2 | Q10: 3.8
B11: Leading 5 causes combined | C11: 483 | D11: 93.4 | E11: 322.6 | H11: Leading 5 causes combined | I11: 363 | J11: 92.1 | K11: 256.8 | N11: Leading 5 causes combined | O11: 845 | P11: 92.8 | Q11: 290.3
B12: All causes | C12: 517 | D12: 100 | E12: 345.3 | H12: All causes | I12: 394 | J12: 100 | K12: 278.8 | N12: All causes | O12: 911 | P12: 100 | Q12: 313
A13: 1–14 | G13: 1–14 | M13: 1–14
A14: 1 | B14: Land transport accidents (V01–V89, Y85) | C14: 34 | D14: 12.8 | E14: 1.5 | G14: 1 | H14: Land transport accidents (V01–V89, Y85) | I14: 20 | J14: 9.7 | K14: 0.9 | M14: 1 | N14: Land transport accidents (V01–V89, Y85) | O14: 54 | P14: 11.4 | Q14: 1.2
A15: 2 | B15: Certain conditions originating in the perinatal period, congenital malformations, deformations and chromosomal abnormalities (P00–P96, Q00–Q99 excl. P28.5) | C15: 22 | D15: 8.3 | E15: 1 | G15: 2 | H15: Brain cancer (C71) | I15: 18 | J15: 8.7 | K15: 0.8 | M15: 2 | N15: Certain conditions originating in the perinatal period, congenital malformations, deformations and chromosomal abnormalities (P00–P96, Q00–Q99 excl. P28.5) | O15: 39 | P15: 8.3 | Q15: 0.9
A16: 3 | B16: Brain cancer (C71) | C16: 18 | D16: 6.8 | E16: 0.8 | G16: 3 | H16: Certain conditions originating in the perinatal period, congenital malformations, deformations and chromosomal abnormalities (P00–P96, Q00–Q99 excl. P28.5) | I16: 17 | J16: 8.3 | K16: 0.8 | M16: 3 | N16: Brain cancer (C71) | O16: 36 | P16: 7.6 | Q16: 0.8
A17: 4 | B17: Other ill-defined causes (R00–R94, R96–R99, I46.9, I95.9, I99, J96.0, J96.9, P28.5) | C17: 14 | D17: 5.3 | E17: 0.6 | G17: 4 | H17: Suicide (X60–X84, Y87.0) | I17: 14 | J17: 6.8 | K17: 0.6 | M17: 4 | N17: Suicide (X60–X84, Y87.0) | O17: 27 | P17: 5.7 | Q17: 0.6
A18: 5 | B18: Suicide (X60–X84, Y87.0) | C18: 13 | D18: 4.9 | E18: 0.6 | G18: 5 | H18: Influenza and pneumonia (J09–J18) | I18: 10 | J18: 4.9 | K18: 0.5 | M18: 5 | N18: Accidental drowning and submersion (W65–W74) | O18: 22 | P18: 4.7 | Q18: 0.5
A19: 5 | B19: Accidental drowning and submersion (W65–W74) | C19: 13 | D19: 4.9 | E19: 0.6 | G19: 6 | H19: Accidental drowning and submersion (W65–W74) | I19: 9 | J19: 4.4 | K19: 0.4 | M19: 5 | N19: Influenza and pneumonia (J09–J18) | O19: 22 | P19: 4.7 | Q19: 0.5
A20: 7 | B20: Influenza and pneumonia (J09–J18) | C20: 12 | D20: 4.5 | E20: 0.5 | G20: 6 | H20: Leukaemia (C91–C95) | I20: 9 | J20: 4.4 | K20: 0.4 | M20: 7 | N20: Other ill-defined causes (R00–R94, R96–R99, I46.9, I95.9, I99, J96.0, J96.9, P28.5) | O20: 20 | P20: 4.2 | Q20: 0.4
A21: 8 | B21: Selected metabolic disorders excl. dehydration (E70–E89 excl. E86, E87) | C21: 11 | D21: 4.1 | E21: 0.5 | G21: 8 | H21: Cerebral palsy and other paralytic syndromes (G80–G83) | I21: 8 | J21: 3.9 | K21: 0.4 | M21: 8 | N21: Selected metabolic disorders excl. dehydration (E70–E89 excl. E86, E87) | O21: 19 | P21: 4 | Q21: 0.4
A22: 9 | B22: Exposure to smoke, fire and flames (X00–X09) | C22: 9 | D22: 3.4 | E22: 0.4 | G22: 8 | H22: Selected metabolic disorders excl. dehydration (E70–E89 excl. E86, E87) | I22: 8 | J22: 3.9 | K22: 0.4 | M22: 9 | N22: Cerebral palsy and other paralytic syndromes (G80–G83) | O22: 16 | P22: 3.4 | Q22: 0.4
A23: 9 | B23: Malignant neoplasms of thyroid and other endocrine glands (C73–C75) | C23: 9 | D23: 3.4 | E23: 0.4 | G23: 10 | H23: Malignant neoplasms of thyroid and other endocrine glands (C73–C75) | I23: 7 | J23: 3.4 | K23: 0.3 | M23: 9 | N23: Malignant neoplasms of thyroid and other endocrine glands (C73–C75) | O23: 16 | P23: 3.4 | Q23: 0.4
G24: 10 | H24: Septicaemia (A40–A41) | I24: 7 | J24: 3.4 | K24: 0.3
B25: Leading 10 causes combined | C25: 155 | D25: 58.3 | E25: 6.7 | H25: Leading 10 causes combined | I25: 127 | J25: 61.7 | K25: 5.8 | N25: Leading 10 causes combined | O25: 271 | P25: 57.4 | Q25: 6
B26: All causes | C26: 266 | D26: 100 | E26: 11.5 | H26: All causes | I26: 206 | J26: 100 | K26: 9.4 | N26: All causes | O26: 472 | P26: 100 | Q26: 10.5
A27: 15–24 | G27: 15–24 | M27: 15–24
A28: 1 | B28: Suicide (X60–X84, Y87.0) | C28: 259 | D28: 32.3 | E28: 15 | G28: 1 | H28: Suicide (X60–X84, Y87.0) | I28: 106 | J28: 34.4 | K28: 6.6 | M28: 1 | N28: Suicide (X60–X84, Y87.0) | O28: 365 | P28: 32.9 | Q28: 10.9
A29: 2 | B29: Land transport accidents (V01–V89, Y85) | C29: 195 | D29: 24.3 | E29: 11.3 | G29: 2 | H29: Land transport accidents (V01–V89, Y85) | I29: 51 | J29: 16.6 | K29: 3.2 | M29: 2 | N29: Land transport accidents (V01–V89, Y85) | O29: 246 | P29: 22.1 | Q29: 7.4
A30: 3 | B30: Accidental poisoning (X40–X49) | C30: 46 | D30: 5.7 | E30: 2.7 | G30: 3 | H30: Other ill-defined causes (R00–R94, R96–R99, I46.9, I95.9, I99, J96.0, J96.9, P28.5) | I30: 17 | J30: 5.5 | K30: 1.1 | M30: 3 | N30: Accidental poisoning (X40–X49) | O30: 56 | P30: 5 | Q30: 1.7
A31: 4 | B31: Other ill-defined causes (R00–R94, R96–R99, I46.9, I95.9, I99, J96.0, J96.9, P28.5) | C31: 32 | D31: 4 | E31: 1.9 | G31: 4 | H31: Event of undetermined intent (Y10–Y34, Y87.2) | I31: 11 | J31: 3.6 | K31: 0.7 | M31: 4 | N31: Other ill-defined causes (R00–R94, R96–R99, I46.9, I95.9, I99, J96.0, J96.9, P28.5) | O31: 49 | P31: 4.4 | Q31: 1.5
A32: 5 | B32: Assault (X85–Y09, Y87.1) | C32: 26 | D32: 3.2 | E32: 1.5 | G32: 5 | H32: Accidental poisoning (X40–X49) | I32: 10 | J32: 3.2 | K32: 0.6 | M32: 5 | N32: Event of undetermined intent (Y10–Y34, Y87.2) | O32: 32 | P32: 2.9 | Q32: 1
A33: 6 | B33: Accidental drowning and submersion (W65–W74) | C33: 22 | D33: 2.7 | E33: 1.3 | G33: 6 | H33: Epilepsy and status epilepticus (G40, G41) | I33: 8 | J33: 2.6 | K33: 0.5 | M33: 6 | N33: Assault (X85–Y09, Y87.1) | O33: 29 | P33: 2.6 | Q33: 0.9
A34: 7 | B34: Event of undetermined intent (Y10–Y34, Y87.2) | C34: 21 | D34: 2.6 | E34: 1.2 | G34: 7 | H34: Malignant neoplasms of bone and articular cartilage (C40–C41) | I34: 6 | J34: 1.9 | K34: 0.4 | M34: 7 | N34: Accidental drowning and submersion (W65–W74) | O34: 24 | P34: 2.2 | Q34: 0.7
A35: 8 | B35: Leukaemia (C91–C95) | C35: 17 | D35: 2.1 | E35: 1 | G35: 7 | H35: Leukaemia (C91–C95) | I35: 6 | J35: 1.9 | K35: 0.4 | M35: 8 | N35: Leukaemia (C91–C95) | O35: 23 | P35: 2.1 | Q35: 0.7
A36: 9 | B36: Malignant neoplasms of bone and articular cartilage (C40–C41) | C36: 14 | D36: 1.7 | E36: 0.8 | G36: 9 | H36: Certain conditions originating in the perinatal period, congenital malformations, deformations and chromosomal abnormalities (P00–P96, Q00–Q99 excl. P28.5) | I36: 5 | J36: 1.6 | K36: 0.3 | M36: 9 | N36: Epilepsy and status epilepticus (G40, G41) | O36: 20 | P36: 1.8 | Q36: 0.6
A37: 10 | B37: Certain conditions originating in the perinatal period, congenital malformations, deformations and chromosomal abnormalities (P00–P96, Q00–Q99 excl. P28.5) | C37: 13 | D37: 1.6 | E37: 0.8 | G37: 9 | H37: Influenza and pneumonia (J09–J18) | I37: 5 | J37: 1.6 | K37: 0.3 | M37: 9 | N37: Malignant neoplasms of bone and articular cartilage (C40–C41) | O37: 20 | P37: 1.8 | Q37: 0.6
G38: 9 | H38: Heart failure and complications and ill-defined heart disease (I50–I51) | I38: 5 | J38: 1.6 | K38: 0.3
B39: Leading 10 causes combined | C39: 645 | D39: 80.3 | E39: 37.4 | H39: Leading 10 causes combined | I39: 230 | J39: 74.7 | K39: 14.3 | N39: Leading 10 causes combined | O39: 864 | P39: 77.8 | Q39: 25.9
B40: All causes | C40: 803 | D40: 100 | E40: 46.5 | H40: All causes | I40: 308 | J40: 100 | K40: 19.1 | N40: All causes | O40: 1111 | P40: 100 | Q40: 33.3
...

Sheet Table S4.1
A1: Table S4.1: Deaths due to COVID-19, number and age-specific rates, by age and sex, 2023
A2: Back to contents
B3: Males | E3: Females | H3: Persons
A4: Age group | B4: Number | C4: ASR (deaths per 100,000) | E4: Number | F4: ASR (deaths per 100,000) | H4: Number | I4: ASR (deaths per 100,000)
A5: 0–14 | B5: 4 | C5: 0.2 | E5: 0 | F5: n.a. | H5: 4 | I5: 0.1
A6: 15–29 | B6: 3 | C6: 0.1 | E6: 1 | F6: 0 | H6: 4 | I6: 0.1
A7: 30–34 | B7: 4 | C7: 0.4 | E7: 5 | F7: 0.5 | H7: 9 | I7: 0.5
A8: 35–39 | B8: 2 | C8: 0.2 | E8: 5 | F8: 0.5 | H8: 7 | I8: 0.4
A9: 40–44 | B9: 8 | C9: 0.9 | E9: 4 | F9: 0.4 | H9: 12 | I9: 0.7
A10: 45–49 | B10: 10 | C10: 1.3 | E10: 7 | F10: 0.9 | H10: 17 | I10: 1.1
A11: 50–54 | B11: 24 | C11: 2.9 | E11: 12 | F11: 1.4 | H11: 36 | I11: 2.1
A12: 55–59 | B12: 28 | C12: 3.7 | E12: 17 | F12: 2.2 | H12: 45 | I12: 2.9
A13: 60–64 | B13: 63 | C13: 8.5 | E13: 49 | F13: 6.3 | H13: 112 | I13: 7.4
A14: 65–69 | B14: 128 | C14: 20.1 | E14: 80 | F14: 11.6 | H14: 208 | I14: 15.7
A15: 70–74 | B15: 214 | C15: 38.6 | E15: 118 | F15: 19.6 | H15: 332 | I15: 28.7
A16: 75–79 | B16: 351 | C16: 78.8 | E16: 224 | F16: 46.2 | H16: 575 | I16: 61.8
A17: 80–84 | B17: 497 | C17: 184.8 | E17: 372 | F17: 118.4 | H17: 869 | I17: 149
... A19: All ages | B19: 2644 | C19: 20 | E19: 2357 | F19: 17.6 | H19: 5001 | I19: 18.8
A20: ASR | B20: age-standardised rate
A21: Notes
A22: 1. Year refers to year of registration of death. Deaths registered in 2023 are based on the preliminary version of cause of death data and are subject to further revision by the Australian Bureau of Statistics (ABS).
A23: 2. Deaths from COVID-19 are coded to ICD-10 codes U07.1 (COVID-19, virus identified), U07.2 (COVID-19, virus not identified) or U10.9 (Multisystem inflammatory syndrome associated with COVID-19, unspecified). In this table, only deaths where COVID-19 was the underlying cause of death are included.
A24: 3. Age-specific rates are calculated using the sum of estimated resident populations at 30 June for each year, sex and age group. Rates are expressed as deaths per 100,000 population.
A25: Source: AIHW (2025) General Record of Incidence of Mortality (GRIM) books (2023): Coronavirus disease 2019 (COVID-19), AIHW, Australian Government. https://www.aihw.gov.au/reports/life-expectancy-deaths/grim-books/contents/grim-excel-workbooks

Sheet Table S5.1
A1: Table S5.1: Potentially avoidable deaths (among people aged under 75), numbers, per cent and rates, by sex, 1997–2023
A2: Back to contents
B3: Males | G3: Females | L3: Persons
A4: Year | B4: Number | C4: Per cent | D4: Crude rate (deaths per 100,000) | E4: ASR (deaths per 100,000) | G4: Number | H4: Per cent | I4: Crude rate (deaths per 100,000) | J4: ASR (deaths per 100,000) | L4: Number | M4: Per cent | N4: Crude rate (deaths per 100,000) | O4: ASR (deaths per 100,000)
A5: 1997 | B5: 21270 | C5: 59.8 | D5: 241.8 | E5: 252.9 | G5: 11942 | H5: 58.1 | I5: 137.5 | J5: 136.2 | L5: 33212 | M5: 59.2 | N5: 190 | O5: 193.2
A6: 1998 | B6: 20550 | C6: 59.3 | D6: 231.8 | E6: 240.4 | G6: 11304 | H6: 57.4 | I6: 129 | J6: 127.5 | L6: 31854 | M6: 58.6 | N6: 180.7 | O6: 182.8
A7: 1999 | B7: 20232 | C7: 59.3 | D7: 226.2 | E7: 232.9 | G7: 10858 | H7: 56.2 | I7: 122.7 | J7: 121 | L7: 31090 | M7: 58.2 | N7: 174.8 | O7: 176
A8: 2000 | B8: 19218 | C8: 58.5 | D8: 212.8 | E8: 218 | G8: 10846 | H8: 56.8 | I8: 121.4 | J8: 119.4 | L8: 30064 | M8: 57.9 | N8: 167.3 | O8: 167.9
A9: 2001 | B9: 18857 | C9: 58.4 | D9: 206.6 | E9: 210.4 | G9: 10493 | H9: 55.8 | I9: 116.1 | J9: 113.9 | L9: 29350 | M9: 57.4 | N9: 161.6 | O9: 161.5
A10: 2002 | B10: 18366 | C10: 57.5 | D10: 199.1 | E10: 201.8 | G10: 10306 | H10: 54.1 | I10: 112.9 | J10: 110.4 | L10: 28672 | M10: 56.2 | N10: 156.2 | O10: 155.6
A11: 2003 | B11: 17950 | C11: 56.8 | D11: 192.6 | E11: 194.6 | G11: 9863 | H11: 53.7 | I11: 106.9 | J11: 104.3 | L11: 27813 | M11: 55.7 | N11: 150 | O11: 148.9
A12: 2004 | B12: 17158 | C12: 55.6 | D12: 182.3 | E12: 183.4 | G12: 9552 | H12: 52.8 | I12: 102.5 | J12: 99.5 | L12: 26710 | M12: 54.6 | N12: 142.6 | O12: 140.9
A13: 2005 | B13: 16702 | C13: 55.4 | D13: 175.5 | E13: 175.3 | G13: 9212 | H13: 51.8 | I13: 97.8 | J13: 94.5 | L13: 25914 | M13: 54.1 | N13: 136.8 | O13: 134.4
A14: 2006 | B14: 16338 | C14: 54.7 | D14: 169.5 | E14: 168.1 | G14: 9173 | H14: 51.8 | I14: 96.1 | J14: 92.5 | L14: 25511 | M14: 53.7 | N14: 133 | O14: 129.9
A15: 2007 | B15: 16341 | C15: 53.8 | D15: 166.4 | E15: 163.5 | G15: 9348 | H15: 50.9 | I15: 96.3 | J15: 91.5 | L15: 25689 | M15: 52.7 | N15: 131.5 | O15: 127.2
A16: 2008 | B16: 16790 | C16: 54 | D16: 167.4 | E16: 163.7 | G16: 9596 | H16: 51.6 | I16: 96.9 | J16: 91.4 | L16: 26386 | M16: 53.1 | N16: 132.4 | O16: 127.2
... A31: 2023 | B31: 17805 | C31: 49.5 | D31: 144.8 | E31: 126.1 | G31: 10307 | H31: 45.8 | I31: 83.9 | J31: 69.2 | L31: 28112 | M31: 48.1 | N31: 114.4 | O31: 97
A32: ASR | B32: age-standardised rate
A33: Notes
A34: 1. Year refers to year of registration of death. Deaths registered in 2020 and earlier are based on the final version of cause of death data; deaths registered in 2021 are based on the revised version; deaths registered in 2022 and 2023 are based on the preliminary version. Revised and preliminary versions are subject to further revision by the Australian Bureau of Statistics.
A35: 2. Comparisons of potentially avoidable deaths to years which include deaths that are not in final verison (2021, 2022, 2023) should be interpreted with caution.
A36: 3. Data is presented by year of registration of death. Prior to the 2022 data release, data was presented by the reference year in which the death was received and processed by the Australian Bureau of Statistics. As a result, data in this table may not equal previously published data for these years. For more detail, refer to Data collection: Presentation of mortality data in Causes of death, Australia, methodology, 2022 (https://www.abs.gov.au/methodologies/causes-death-australia-methodology/2022#data-collection).
A37: 4. Potentially avoidable deaths are deaths from conditions that are potentially preventable through individualised care and/or treatable through existing primary or hospital care. They are classified using nationally agreed definitions based on cause of death for people aged less than 75 (AIHW 2021. National Healthcare Agreement: PI 16—Potentially avoidable deaths, 2022. Viewed 07 January 2025, <https://meteor.aihw.gov.au/content/index.phtml/itemId/740864>).
A38: 5. Per cent of all deaths of people aged under 75 years.
A39: 6. Rates are expressed as deaths per 100,000 population. Crude rates are calculated using the estimated resident population at 30 June for each year. Age-standardised rates are directly standardised to the Australian estimated resident population at 30 June 2001.
A40: Source: AIHW National Mortality Database.

Sheet Table S5.2
A1: Table S5.2: Potentially avoidable causes of death (among people aged under 75), number, per cent and rates (deaths per 100,000 population), by sex and broad cause groups, 2023
A2: Back to contents
A3: Males | G3: Females | M3: Persons
A4: Broad cause of death group | B4: Number | C4: Per cent | D4: Crude rate (deaths per 100,000) | E4: ASR (deaths per 100,000) | G4: Broad cause of death group | H4: Number | I4: Per cent | J4: Crude rate (deaths per 100,000) | K4: ASR (deaths per 100,000) | M4: Broad cause of death group | N4: Number | O4: Per cent | P4: Crude rate (deaths per 100,000) | Q4: ASR (deaths per 100,000)
A5: Infections | B5: 517 | C5: 1.4 | D5: 4.2 | E5: 3.6 | G5: Infections | H5: 411 | I5: 1.8 | J5: 3.3 | K5: 2.7 | M5: Infections | N5: 928 | O5: 1.6 | P5: 3.8 | Q5: 3.1
A6: Cancer | B6: 3168 | C6: 8.8 | D6: 25.8 | E6: 21 | G6: Cancer | H6: 3266 | I6: 14.5 | J6: 26.6 | K6: 21.7 | M6: Cancer | N6: 6434 | O6: 11 | P6: 26.2 | Q6: 21.3
A7: Diabetes | B7: 1169 | C7: 3.3 | D7: 9.5 | E7: 7.8 | G7: Diabetes | H7: 669 | I7: 3 | J7: 5.4 | K7: 4.2 | M7: Diabetes | N7: 1838 | O7: 3.1 | P7: 7.5 | Q7: 6
A8: Diseases of the circulatory system | B8: 5687 | C8: 15.8 | D8: 46.3 | E8: 38.3 | G8: Diseases of the circulatory system | H8: 2459 | I8: 10.9 | J8: 20 | K8: 15.5 | M8: Diseases of the circulatory system | N8: 8146 | O8: 13.9 | P8: 33.1 | Q8: 26.6
A9: Diseases of the genitourinary system | B9: 234 | C9: 0.7 | D9: 1.9 | E9: 1.5 | G9: Diseases of the genitourinary system | H9: 155 | I9: 0.7 | J9: 1.3 | K9: 1 | M9: Diseases of the genitourinary system | N9: 389 | O9: 0.7 | P9: 1.6 | Q9: 1.2
A10: Diseases of the respiratory system | B10: 1395 | C10: 3.9 | D10: 11.3 | E10: 9 | G10: Diseases of the respiratory system | H10: 1219 | I10: 5.4 | J10: 9.9 | K10: 7.4 | M10: Diseases of the respiratory system | N10: 2614 | O10: 4.5 | P10: 10.6 | Q10: 8.1
A11: Diseases of the digestive system | B11: 71 | C11: 0.2 | D11: 0.6 | E11: 0.5 | G11: Diseases of the digestive system | H11: 35 | I11: 0.2 | J11: 0.3 | K11: 0.2 | M11: Diseases of the digestive system | N11: 106 | O11: 0.2 | P11: 0.4 | Q11: 0.4
A12: Maternal & infant causes | B12: 304 | C12: 0.8 | D12: 2.5 | E12: 2.7 | G12: Maternal & infant causes | H12: 220 | I12: 1 | J12: 1.8 | K12: 2.1 | M12: Maternal & infant causes | N12: 524 | O12: 0.9 | P12: 2.1 | Q12: 2.4
A13: Other conditions | B13: 0 | C13: .. | D13: .. | E13: .. | G13: Other conditions | H13: 17 | I13: 0.1 | J13: 0.1 | K13: 0.1 | M13: Other conditions | N13: 17 | O13: 0 | P13: 0.1 | Q13: 0.1
A14: External causes | B14: 5260 | C14: 14.6 | D14: 42.8 | E14: 41.6 | G14: External causes | H14: 1856 | I14: 8.2 | J14: 15.1 | K14: 14.3 | M14: External causes | N14: 7116 | O14: 12.2 | P14: 29 | Q14: 27.8
A15: Total potentially avoidable | B15: 17805 | C15: 49.5 | D15: 144.8 | E15: 126.1 | G15: Total potentially avoidable | H15: 10307 | I15: 45.8 | J15: 83.9 | K15: 69.2 | M15: Total potentially avoidable | N15: 28112 | O15: 48.1 | P15: 114.4 | Q15: 97
A16: All other deaths less than age 75 | B16: 18150 | C16: 50.5 | D16: 147.6 | E16: 123 | G16: All other deaths less than age 75 | H16: 12206 | I16: 54.2 | J16: 99.4 | K16: 78.3 | M16: All other deaths less than age 75 | N16: 30356 | O16: 51.9 | P16: 123.5 | Q16: 100
A17: Total deaths less than age 75 | B17: 35955 | C17: 100 | D17: 292.4 | E17: 249 | G17: Total deaths less than age 75 | H17: 22513 | I17: 100 | J17: 183.3 | K17: 147.5 | M17: Total deaths less than age 75 | N17: 58468 | O17: 100 | P17: 237.9 | Q17: 197.1
A18: ASR age-standardised rate
A19: COPD Chronic obstructive pulmonary disease
A20: .. not applicable
A21: Notes
A22: 1. Deaths are counted according to year of registration of death.
A23: 2. Deaths registered in 2023 are based on the preliminary versionand are subject to further revision by the Australian Bureau of Statistics.
A24: 3. Potentially avoidable deaths are deaths from conditions that are potentially preventable through individualised care and/or treatable through existing primary or hospital care. They are classified using nationally agreed definitions based on cause of death for people aged less than 75 (AIHW 2021. National Healthcare Agreement: PI 16—Potentially avoidable deaths, 2022. Viewed 07 January 2025, <https://meteor.aihw.gov.au/content/index.phtml/itemId/740864>).
A25: 4. Other conditions includes complications of pregnancy, labour or the puerperium.
A26: 5. Per cent of total deaths less than age 75.
A27: Source: AIHW National Mortality Database.

Sheet Table S5.3
A1: Table S5.3: Leading potentially avoidable deaths (among people aged under 75), number, per cent and rates (deaths per 100,000 population), by sex, 2023
A2: Back to contents
B3: Males | I3: Females | P3: Persons
A4: Rank | B4: Cause of death | C4: Number | D4: Per cent | E4: Crude rate (deaths per 100,000) | F4: ASR (deaths per 100,000) | H4: Rank | I4: Cause of death | J4: Number | K4: Per cent | L4: Crude rate (deaths per 100,000) | M4: ASR (deaths per 100,000) | O4: Rank | P4: Cause of death | Q4: Number | R4: Per cent | S4: Crude rate (deaths per 100,000) | T4: ASR (deaths per 100,000)
A5: 1 | B5: Coronary (ischaemic) heart disease | C5: 3888 | D5: 10.8 | E5: 31.6 | F5: 26.3 | H5: 1 | I5: Breast cancer | J5: 1667 | K5: 7.4 | L5: 13.6 | M5: 11 | O5: 1 | P5: Coronary (ischaemic) heart disease | Q5: 5039 | R5: 8.6 | S5: 20.5 | T5: 16.5
A6: 2 | B6: Suicide and self-inflicted injuries | C6: 2212 | D6: 6.2 | E6: 18 | F6: 17.7 | H6: 2 | I6: Coronary (ischaemic) heart disease | J6: 1151 | K6: 5.1 | L6: 9.4 | M6: 7.2 | O6: 2 | P6: Suicide and self-inflicted injuries | Q6: 2945 | R6: 5 | S6: 12 | T6: 11.7
A7: 3 | B7: Cancer of the colon, sigmoid, rectum and anus | C7: 1362 | D7: 3.8 | E7: 11.1 | F7: 9.3 | H7: 3 | I7: COPD | J7: 1100 | K7: 4.9 | L7: 9 | M7: 6.5 | O7: 3 | P7: COPD | Q7: 2414 | R7: 4.1 | S7: 9.8 | T7: 7.4
A8: 4 | B8: COPD | C8: 1314 | D8: 3.7 | E8: 10.7 | F8: 8.4 | H8: 4 | I8: Cancer of the colon, sigmoid, rectum and anus | J8: 973 | K8: 4.3 | L8: 7.9 | M8: 6.5 | O8: 4 | P8: Cancer of the colon, sigmoid, rectum and anus | Q8: 2335 | R8: 4 | S8: 9.5 | T8: 7.8
A9: 5 | B9: Diabetes | C9: 1169 | D9: 3.3 | E9: 9.5 | F9: 7.8 | H9: 5 | I9: Cerebrovascular diseases | J9: 815 | K9: 3.6 | L9: 6.6 | M9: 5.2 | O9: 5 | P9: Diabetes | Q9: 1838 | R9: 3.1 | S9: 7.5 | T9: 6
A10: 6 | B10: Cerebrovascular diseases | C10: 1019 | D10: 2.8 | E10: 8.3 | F10: 6.8 | H10: 6 | I10: Suicide and self-inflicted injuries | J10: 733 | K10: 3.3 | L10: 6 | M10: 5.9 | O10: 6 | P10: Cerebrovascular diseases | Q10: 1834 | R10: 3.1 | S10: 7.5 | T10: 6
A11: 7 | B11: Transport accidents | C11: 949 | D11: 2.6 | E11: 7.7 | F11: 7.5 | H11: 7 | I11: Diabetes | J11: 669 | K11: 3 | L11: 5.4 | M11: 4.2 | O11: 7 | P11: Breast cancer | Q11: 1667 | R11: 2.9 | S11: 6.8 | T11: 5.6
A12: 8 | B12: Accidental poisoning | C12: 853 | D12: 2.4 | E12: 6.9 | F12: 7.1 | H12: 8 | I12: Accidental poisoning | J12: 321 | K12: 1.4 | L12: 2.6 | M12: 2.5 | O12: 8 | P12: Transport accidents | Q12: 1227 | R12: 2.1 | S12: 5 | T12: 4.9
A13: 9 | B13: Prostate cancer | C13: 800 | D13: 2.2 | E13: 6.5 | F13: 5 | H13: 9 | I13: Selected invasive infections | J13: 313 | K13: 1.4 | L13: 2.5 | M13: 2 | O13: 9 | P13: Accidental poisoning | Q13: 1174 | R13: 2 | S13: 4.8 | T13: 4.8
A14: 10 | B14: Skin cancer | C14: 596 | D14: 1.7 | E14: 4.8 | F14: 4 | H14: 10 | I14: Transport accidents | J14: 278 | K14: 1.2 | L14: 2.3 | M14: 2.2 | O14: 10 | P14: Skin cancer | Q14: 836 | R14: 1.4 | S14: 3.4 | T14: 2.8
A15: 11 | B15: Falls | C15: 364 | D15: 1 | E15: 3 | F15: 2.4 | H15: 11 | I15: Skin cancer | J15: 240 | K15: 1.1 | L15: 2 | M15: 1.6 | O15: 11 | P15: Prostate cancer | Q15: 800 | R15: 1.4 | S15: 3.3 | T15: 2.4
A16: 12 | B16: Selected invasive infections | C16: 364 | D16: 1 | E16: 3 | F16: 2.5 | H16: 12 | I16: Complications of the perinatal period | J16: 220 | K16: 1 | L16: 1.8 | M16: 2.1 | O16: 12 | P16: Selected invasive infections | Q16: 677 | R16: 1.2 | S16: 2.8 | T16: 2.3
... A24: 20 | B24: Accidental drowning and submersion | C24: 135 | D24: 0.4 | E24: 1.1 | F24: 1.1 | H24: 20 | I24: Kidney cancer | J24: 110 | K24: 0.5 | L24: 0.9 | M24: 0.7 | O24: 20 | P24: Cervical cancer | Q24: 210 | R24: 0.4 | S24: 0.9 | T24: 0.8
B25: Total potentially avoidable | C25: 17805 | D25: 49.5 | E25: 144.8 | F25: 126.1 | I25: Total potentially avoidable | J25: 10307 | K25: 45.8 | L25: 83.9 | M25: 69.2 | P25: Total potentially avoidable | Q25: 28112 | R25: 48.1 | S25: 114.4 | T25: 97
B26: All other deaths less than age 75 | C26: 18150 | D26: 50.5 | E26: 147.6 | F26: 123 | I26: All other deaths less than age 75 | J26: 12206 | K26: 54.2 | L26: 99.4 | M26: 78.3 | P26: All other deaths less than age 75 | Q26: 30356 | R26: 51.9 | S26: 123.5 | T26: 100
B27: Total deaths less than age 75 | C27: 35955 | D27: 100 | E27: 292.4 | F27: 249 | I27: Total deaths less than age 75 | J27: 22513 | K27: 100 | L27: 183.3 | M27: 147.5 | P27: Total deaths less than age 75 | Q27: 58468 | R27: 100 | S27: 237.9 | T27: 197.1
A28: ASR | B28: age-standardised rate
A29: COPD | B29: Chronic obstructive pulmonary disease
A30: Notes
A31: 1. Deaths are counted according to year of registration of death.
A32: 2. Deaths registered in 2023 are based on the preliminary versionand are subject to further revision by the Australian Bureau of Statistics.
A33: 3. Potentially avoidable deaths are deaths from conditions that are potentially preventable through individualised care and/or treatable through existing primary or hospital care. They are classified using nationally agreed definitions based on cause of death for people aged less than 75 (AIHW 2021. National Healthcare Agreement: PI 16—Potentially avoidable deaths, 2022. Viewed 07 January 2025, <https://meteor.aihw.gov.au/content/index.phtml/itemId/740864>).
A34: 4. Leading 20 causes of potentially avoidable deaths. Deaths with counts less than 20 were excluded from the table. Any causes of death with sex breakdowns resulting in the re-identification of small numbers were also excluded.
A35: Source: AIHW National Mortality Database.

Sheet Table S6.1
A1: Table S6.1: Deaths, number and rates, by sex, 1907–2023
A2: Back to contents
B3: Males | F3: Females | J3: Persons
A4: Year | B4: Number | C4: Crude rate (deaths per 100,000) | D4: ASR (deaths per 100,000) | F4: Number | G4: Crude rate (deaths per 100,000) | H4: ASR (deaths per 100,000) | J4: Number | K4: Crude rate (deaths per 100,000) | L4: ASR (deaths per 100,000)
A5: 1907 | B5: 25939 | C5: 1190.4 | D5: 2234.2 | F5: 19366 | G5: 966.6 | H5: 1844.4 | J5: 45305 | K5: 1083.2 | L5: 2054.2
A6: 1908 | B6: 26632 | C6: 1203.7 | D6: 2279.6 | F6: 19794 | G6: 971.2 | H6: 1851.2 | J6: 46426 | K6: 1092.2 | L6: 2079.3
A7: 1909 | B7: 25514 | C7: 1136 | D7: 2130.5 | F7: 18658 | G7: 900.2 | H7: 1691.4 | J7: 44172 | K7: 1022.8 | L7: 1925.2
A8: 1910 | B8: 26154 | C8: 1147.3 | D8: 2106.4 | F8: 19436 | G8: 922.3 | H8: 1735.9 | J8: 45590 | K8: 1039.2 | L8: 1933
A9: 1911 | B9: 27591 | C9: 1192.8 | D9: 2241.7 | F9: 20278 | G9: 946.7 | H9: 1820.5 | J9: 47869 | K9: 1074.5 | L9: 2043.4
A10: 1912 | B10: 30285 | C10: 1283.8 | D10: 2322 | F10: 21892 | G10: 996.9 | H10: 1851.6 | J10: 52177 | K10: 1145.5 | L10: 2099.8
A11: 1913 | B11: 29859 | C11: 1241.6 | D11: 2229.4 | F11: 21930 | G11: 974.6 | H11: 1798.2 | J11: 51789 | K11: 1112.5 | L11: 2025
A12: 1914 | B12: 29835 | C12: 1217.4 | D12: 2188.2 | F12: 21885 | G12: 949.7 | H12: 1778 | J12: 51720 | K12: 1087.7 | L12: 1992.5
A13: 1915 | B13: 30654 | C13: 1227.8 | D13: 2255.1 | F13: 22128 | G13: 938.2 | H13: 1768.9 | J13: 52782 | K13: 1087.2 | L13: 2020.8
A14: 1916 | B14: 31018 | C14: 1220 | D14: 2261.8 | F14: 23179 | G14: 960.8 | H14: 1779.4 | J14: 54197 | K14: 1093.8 | L14: 2027.7
A15: 1917 | B15: 27609 | C15: 1066.7 | D15: 2040.2 | F15: 20420 | G15: 827.8 | H15: 1595 | J15: 48029 | K15: 950.1 | L15: 1822.8
A16: 1918 | B16: 28585 | C16: 1085.1 | D16: 2087.4 | F16: 21664 | G16: 859.4 | H16: 1681.3 | J16: 50249 | K16: 974.7 | L16: 1889.4
... A121: 2023 | B121: 96180 | C121: 726.8 | D121: 604.8 | F121: 86951 | G121: 647.9 | H121: 430.9 | J121: 183131 | K121: 687.1 | L121: 512.7
A122: ASR | B122: age-standardised rate
A123: Notes
A124: 1. Year refers to year of registration of death.
A125: 2. Data is presented by year of registration of death. Prior to the 2022 data release, data was presented by the reference year in which the death was received and processed by the Australian Bureau of Statistics. As a result, data in this table may not equal previously published data for these years. For more detail, refer to Data collection: Presentation of mortality data in Causes of death, Australia, methodology, 2022 (https://www.abs.gov.au/methodologies/causes-death-australia-methodology/2022#data-collection)
A126: 3. Rates are calculated using the sum of estimated resident populations at 30 June for each year. Rates are expressed as deaths per 100,000 population.
A127: Source: AIHW (2025) General Record of Incidence of Mortality (GRIM) books (2023): All causes combined, AIHW, Australian Government. https://www.aihw.gov.au/reports/life-expectancy-deaths/grim-books/contents/grim-excel-workbooks

Sheet Table S6.2
A1: Table S6.2: Deaths by broad cause of death, number and rates, 1907–2023
A2: Back to contents
B3: Cardiovascular diseases | F3: Cancers (all neoplasms) | J3: Respiratory diseases | N3: Infectious diseases | R3: Injury and poisoning | V3: Other | Z3: All causes
A4: Year | B4: Number | C4: Crude rate (deaths per 100,000) | D4: ASR (deaths per 100,000) | F4: Number | G4: Crude rate (deaths per 100,000) | H4: ASR (deaths per 100,000) | J4: Number | K4: Crude rate (deaths per 100,000) | L4: ASR (deaths per 100,000) | N4: Number | O4: Crude rate (deaths per 100,000) | P4: ASR (deaths per 100,000) | R4: Number | S4: Crude rate (deaths per 100,000) | T4: ASR (deaths per 100,000) | V4: Number | W4: Crude rate (deaths per 100,000) | X4: ASR (deaths per 100,000) | Z4: Number | AA4: Crude rate (deaths per 100,000) | AB4: ASR (deaths per 100,000)
A5: 1907 | B5: 6854 | C5: 163.87236 | D5: 410.23196 | F5: 3096 | G5: 74.0223 | H5: 163.80931 | J5: 5743 | K5: 137.30945 | L5: 292.95751 | N5: 12606 | O5: 301.397 | P5: 319.62343 | R5: 3172 | S5: 75.839384 | T5: 104.57895 | V5: 13834 | W5: 330.75726 | X5: 763.00474 | Z5: 45305 | AA5: 1083.1978 | AB5: 2054.2059
A6: 1908 | B6: 7241 | C6: 170.35067 | D6: 426.84861 | F6: 3066 | G6: 72.13025 | H6: 157.08047 | J6: 5292 | K6: 124.49879 | L6: 256.3725 | N6: 8859 | O6: 208.41549 | P6: 261.58026 | R6: 3444 | S6: 81.023021 | T6: 109.16768 | V6: 18524 | W6: 435.79281 | X6: 868.21768 | Z6: 46426 | AA6: 1092.211 | AB6: 2079.2672
A7: 1909 | B7: 7085 | C7: 164.05156 | D7: 405.33435 | F7: 3271 | G7: 75.739259 | H7: 162.11542 | J7: 4581 | K7: 106.07201 | L7: 225.07777 | N7: 9085 | O7: 210.3611 | P7: 251.52118 | R7: 3179 | S7: 73.60902 | T7: 95.498475 | V7: 16971 | W7: 392.95963 | X7: 785.6312 | Z7: 44172 | AA7: 1022.7926 | AB7: 1925.1784
A8: 1910 | B8: 7552 | C8: 172.1495 | D8: 424.39335 | F8: 3375 | G8: 76.933868 | H8: 167.99038 | J8: 4251 | K8: 96.902481 | L8: 208.87976 | N8: 8899 | O8: 202.85466 | P8: 245.40003 | R8: 3285 | S8: 74.882298 | T8: 101.14484 | V8: 18228 | W8: 415.51127 | X8: 785.19774 | Z8: 45590 | AA8: 1039.2341 | AB8: 1933.0061
A9: 1911 | B9: 8674 | C9: 194.70236 | D9: 479.7932 | F9: 3476 | G9: 78.024604 | H9: 169.65633 | J9: 5403 | K9: 121.27933 | L9: 251.69233 | N9: 10183 | O9: 228.57438 | P9: 263.5121 | R9: 3582 | S9: 80.40395 | T9: 106.48016 | V9: 16551 | W9: 371.51473 | X9: 772.27468 | Z9: 47869 | AA9: 1074.4994 | AB9: 2043.4088
A10: 1912 | B10: 9199 | C10: 201.95325 | D10: 478.72082 | F10: 3676 | G10: 80.702268 | H10: 169.81969 | J10: 5323 | K10: 116.86022 | L10: 239.89271 | N10: 8020 | O10: 176.06969 | P10: 204.82619 | R10: 3878 | S10: 85.136941 | T10: 111.05135 | V10: 22081 | W10: 484.76245 | X10: 895.46694 | Z10: 52177 | AA10: 1145.4848 | AB10: 2099.7777
A11: 1913 | B11: 9003 | C11: 193.40394 | D11: 459.08799 | F11: 3769 | G11: 80.966285 | H11: 169.85772 | J11: 5004 | K11: 107.49676 | L11: 221.72123 | N11: 9138 | O11: 196.30404 | P11: 235.55606 | R11: 3832 | S11: 82.319662 | T11: 105.66337 | V11: 21043 | W11: 452.04923 | X11: 833.10393 | Z11: 51789 | AA11: 1112.5399 | AB11: 2024.9903
A12: 1914 | B12: 8871 | C12: 186.5602 | D12: 444.4463 | F12: 3838 | G12: 80.714468 | H12: 168.66097 | J12: 5044 | K12: 106.07707 | L12: 216.14602 | N12: 10743 | O12: 225.92901 | P12: 222.75562 | R12: 3804 | S12: 79.999436 | T12: 102.71942 | V12: 19420 | W12: 408.40932 | X12: 837.78827 | Z12: 51720 | AA12: 1087.6895 | AB12: 1992.5166
A13: 1915 | B13: 8477 | C13: 174.60196 | D13: 410.80907 | F13: 3856 | G13: 79.422572 | H13: 163.98608 | J13: 5627 | K13: 115.90011 | L13: 227.66805 | N13: 8355 | O13: 172.0891 | P13: 174.86191 | R13: 3524 | S13: 72.584321 | T13: 98.393009 | V13: 22943 | W13: 472.56018 | X13: 945.03468 | Z13: 52782 | AA13: 1087.1582 | AB13: 2020.7528
A14: 1916 | B14: 8902 | C14: 179.65501 | D14: 422.51406 | F14: 4157 | G14: 83.894167 | H14: 169.94011 | J14: 5659 | K14: 114.20666 | L14: 227.06282 | N14: 6695 | O14: 135.11461 | P14: 146.39631 | R14: 3312 | S14: 66.840866 | T14: 88.791411 | V14: 25472 | W14: 514.06115 | X14: 973.02269 | Z14: 54197 | AA14: 1093.7725 | AB14: 2027.7274
A15: 1917 | B15: 8399 | C15: 166.15029 | D15: 383.62025 | F15: 4216 | G15: 83.401549 | H15: 173.16573 | J15: 4874 | K15: 96.418204 | L15: 198.78177 | N15: 7183 | O15: 142.09519 | P15: 153.73709 | R15: 3187 | S15: 63.045715 | T15: 82.679489 | V15: 20170 | W15: 399.00599 | X15: 830.82527 | Z15: 48029 | AA15: 950.11693 | AB15: 1822.8096
A16: 1918 | B16: 8578 | C16: 166.39924 | D16: 386.17272 | F16: 4420 | G16: 85.740809 | H16: 173.55643 | J16: 6363 | K16: 123.43185 | L16: 270.5248 | N16: 7030 | O16: 136.37056 | P16: 150.58599 | R16: 3151 | S16: 61.124273 | T16: 80.505334 | V16: 20707 | W16: 401.68211 | X16: 828.09653 | Z16: 50249 | AA16: 974.74885 | AB16: 1889.4418
... A121: 2023 | B121: 42597 | C121: 159.822 | D121: 115.38424 | F121: 52348 | G121: 196.4073 | H121: 149.16359 | J121: 15196 | K121: 57.0147 | L121: 41.38002 | N121: 3099 | O121: 11.62731 | P121: 8.48821 | R121: 12441 | S121: 46.67806 | T121: 40.0486 | V121: 57450 | W121: 215.54977 | X121: 158.27462 | Z121: 183131 | AA121: 687.09913 | AB121: 512.73928
A122: ASR | B122: age-standardised rate
A123: Notes
A124: 1. Year refers to year of registration of death. Deaths registered in 2020 and earlier are based on the final version of cause of death data; deaths registered in 2021 are based on the revised version; deaths registered in 2022 and 2023 are based on the preliminary version. Revised and preliminary versions are subject to further revision by the Australian Bureau of Statistics.
A125: 2. Data is presented by year of registration of death. Prior to the 2022 data release, data was presented by the reference year in which the death was received and processed by the Australian Bureau of Statistics. As a result, data in this table may not equal previously published data for these years. For more detail, refer to Data collection: Presentation of mortality data in Causes of death, Australia, methodology, 2022 (https://www.abs.gov.au/methodologies/causes-death-australia-methodology/2022#data-collection)
A126: 3. Broad causes of death are based on underlying cause of death and classified according International Statistical Classification of Diseases and Related Health Problems, 10th revision (ICD-10) chapters: cardiovascular diseases (I00–I99), cancers (C00–D48), respiratory diseases (J00–J48), infectious diseases (A00–B99), injury and poisoning (V01–Y98). Data for chapter-level causes of death are collated from the AIHW General Record of Incidence of Mortality (GRIM) books: GRIM0100 All certain infectious and parasitic diseases (A00–B99), GRIM0200 All neoplasms (C00-D48), GRIM0900 All diseases of the circulatory system (I00–I99), GRIM1000 All diseases of the respiratory system (J00–J99), and GRIM2000 All external causes of morbidity and mortality (V01–Y98)
A127: 4. The broad cause group 'Other' includes deaths that are not included in one of the specified broad causes in this table.
A128: 5. Rates are calculated using the sum of estimated resident populations at 30 June for each year. Rates are expressed as deaths per 100,000 population.
A129: Source: AIHW General Record of Incidence of Mortality (GRIM) books, https://www.aihw.gov.au/reports/life-expectancy-deaths/grim-books/contents/about; AIHW National Mortality Database

Sheet Table S6.3
A1: Table S6.3: Leading underlying causes of death, number, per cent of all deaths and age-standardised death rates, by sex, 2013
A2: Back to contents
A3: Males | G3: Females | M3: Persons
A4: Rank | B4: Cause of death | C4: Number | D4: Per cent | E4: ASR (deaths per 100,000) | G4: Rank | H4: Cause of death | I4: Number | J4: Per cent | K4: ASR (deaths per 100,000) | M4: Rank | N4: Cause of death | O4: Number | P4: Per cent | Q4: ASR (deaths per 100,000)
A5: 1 | B5: Coronary heart disease (I20–I25) | C5: 11083 | D5: 14.6 | E5: 94.4 | G5: 1 | H5: Coronary heart disease (I20–I25) | I5: 8775 | J5: 12.2 | K5: 50.3 | M5: 1 | N5: Coronary heart disease (I20–I25) | O5: 19858 | P5: 13.4 | Q5: 70.5
A6: 2 | B6: Lung cancer (C33, C34) | C6: 5000 | D6: 6.6 | E6: 41.4 | G6: 2 | H6: Dementia including Alzheimer's disease (F01, F03, G30) | I6: 7298 | J6: 10.1 | K6: 40 | M6: 2 | N6: Dementia including Alzheimer's disease (F01, F03, G30) | O6: 10965 | P6: 7.4 | Q6: 37.3
A7: 3 | B7: Cerebrovascular disease (I60–I69) | C7: 4184 | D7: 5.5 | E7: 36.3 | G7: 3 | H7: Cerebrovascular disease (I60–I69) | I7: 6386 | J7: 8.9 | K7: 37 | M7: 3 | N7: Cerebrovascular disease (I60–I69) | O7: 10570 | P7: 7.1 | Q7: 37.1
A8: 4 | B8: Dementia including Alzheimer's disease (F01, F03, G30) | C8: 3667 | D8: 4.8 | E8: 32.4 | G8: 4 | H8: Lung cancer (C33, C34) | I8: 3230 | J8: 4.5 | K8: 23 | M8: 4 | N8: Lung cancer (C33, C34) | O8: 8230 | P8: 5.6 | Q8: 31.3
A9: 5 | B9: Chronic obstructive pulmonary disease (J40–J44) | C9: 3589 | D9: 4.7 | E9: 30.9 | G9: 5 | H9: Chronic obstructive pulmonary disease (J40–J44) | I9: 2896 | J9: 4 | K9: 18.9 | M9: 5 | N9: Chronic obstructive pulmonary disease (J40–J44) | O9: 6485 | P9: 4.4 | Q9: 23.9
A10: 6 | B10: Prostate cancer (C61) | C10: 3127 | D10: 4.1 | E10: 26.9 | G10: 6 | H10: Breast cancer (C50) | I10: 2871 | J10: 4 | K10: 20.5 | M10: 6 | N10: Colorectal cancer (C18–C20, C26.0) | O10: 5326 | P10: 3.6 | Q10: 20
A11: 7 | B11: Colorectal cancer (C18–C20, C26.0) | C11: 2877 | D11: 3.8 | E11: 24.2 | G11: 7 | H11: Colorectal cancer (C18–C20, C26.0) | I11: 2449 | J11: 3.4 | K11: 16.5 | M11: 7 | N11: Diabetes (E10–E14) | O11: 4356 | P11: 2.9 | Q11: 16
A12: 8 | B12: Diabetes (E10–E14) | C12: 2318 | D12: 3 | E12: 19.8 | G12: 8 | H12: Diabetes (E10–E14) | I12: 2038 | J12: 2.8 | K12: 12.8 | M12: 8 | N12: Heart failure and complications and ill-defined heart disease (I50–I51) | O12: 3256 | P12: 2.2 | Q12: 11.3
A13: 9 | B13: Suicide (X60–X84, Y87.0) | C13: 1958 | D13: 2.6 | E13: 16.9 | G13: 9 | H13: Heart failure and complications and ill-defined heart disease (I50–I51) | I13: 1831 | J13: 2.5 | K13: 10.2 | M13: 9 | N13: Prostate cancer (C61) | O13: 3127 | P13: 2.1 | Q13: 11.4
A14: 10 | B14: Cancer of unknown or ill-defined primary site (C26, C39, C76–C80 excl. C26.0) | C14: 1505 | D14: 2 | E14: 12.7 | G14: 10 | H14: Hypertensive disease (I10–I15) | I14: 1393 | J14: 1.9 | K14: 7.7 | M14: 10 | N14: Breast cancer (C50) | O14: 2902 | P14: 2 | Q14: 11
A15: 11 | B15: Heart failure and complications and ill-defined heart disease (I50–I51) | C15: 1425 | D15: 1.9 | E15: 12.4 | G15: 11 | H15: Influenza and pneumonia (J09–J18) | I15: 1370 | J15: 1.9 | K15: 7.8 | M15: 11 | N15: Cancer of unknown or ill-defined primary site (C26, C39, C76–C80 excl. C26.0) | O15: 2864 | P15: 1.9 | Q15: 10.6
A16: 12 | B16: Pancreatic cancer (C25) | C16: 1345 | D16: 1.8 | E16: 11.1 | G16: 12 | H16: Cancer of unknown or ill-defined primary site (C26, C39, C76–C80 excl. C26.0) | I16: 1359 | J16: 1.9 | K16: 8.9 | M16: 12 | N16: Suicide (X60–X84, Y87.0) | O16: 2629 | P16: 1.8 | Q16: 11.2
... A24: 20 | B24: Kidney failure (N17–N19) | C24: 947 | D24: 1.2 | E24: 8.2 | G24: 20 | H24: Other ill-defined causes (R00–R94, R96–R99, I46.9, I95.9, I99, J96.0, J96.9, P28.5) | I24: 807 | J24: 1.1 | K24: 5 | M24: 20 | N24: Leukaemia (C91–C95) | O24: 1657 | P24: 1.1 | Q24: 6.3
B25: Leading 20 causes combined | C25: 50443 | D25: 66.3 | E25: 430.6 | H25: Leading 20 causes combined | I25: 49864 | J25: 69.1 | K25: 302.7 | N25: Leading 20 causes combined | O25: 97170 | P25: 65.5 | Q25: 351.3
B26: All causes | C26: 76134 | D26: 100 | E26: 649.6 | H26: All causes | I26: 72131 | J26: 100 | K26: 452.4 | N26: All causes | O26: 148265 | P26: 100 | Q26: 543.2
A27: ASR | B27: age-standardised rate
A28: .. | B28: not applicable
A29: Notes
A30: 1. Year refers to year of registration of death. Deaths registered in 2013 are based on the final version of cause of death data.
A31: 2. Leading causes of death are based on underlying causes of death and classified using an AIHW-modified version of Becker R, Sivli J, Ma Fat, L'Hours A, Laurenti R (2006). A method for deriving leading causes of death. Bulletin of the World Health Organization 84: 297–304. International Statistical Classification of Diseases and Related Health Problems, 10th revision (ICD-10) codes are presented in parentheses.
A32: 3. Rates are expressed as deaths per 100,000 population. Age-standardised rates are directly standardised to the Australian estimated resident population at 30 June 2001.
A33: Source: AIHW National Mortality Database.

Sheet Table S6.4
A1: Table S6.4: Leading underlying causes of death, number, per cent of all deaths and age-standardised death rates, by sex, 2013–2023
A2: Back to contents
A3: Males | E3: Females | I3: Persons
A4: Cause of death and year | B4: Number | C4: ASR (deaths per 100,000) | E4: Cause of death and year | F4: Number | G4: ASR (deaths per 100,000) | I4: Cause of death and year | J4: Number | K4: ASR (deaths per 100,000)
A5: Coronary heart disease (I20–I25) | E5: Coronary heart disease (I20–I25) | I5: Coronary heart disease (I20–I25)
A6: 2013 | B6: 11083 | C6: 94.449696 | E6: 2013 | F6: 8775 | G6: 50.294179 | I6: 2013 | J6: 19858 | K6: 70.45264
